Workbook

Sheet payrolls
A1: Date | B1: Código | C1: Concepto | D1: Beneficiario | E1: Ingreso | F1: Egreso
A2: 45689 | B2: 2174 | C2: Pago JGG | D2: JGG | E2: 0 | F2: 25000
A3: 45611 | B3: 2174 | C3: Pago JGG | D3: JGG | E3: 0 | F3: 21000
A4: 45551 | B4: 2174 | C4: Pago JGG | D4: JGG | E4: 0 | F4: 19200
A5: 45658 | B5: 2174 | C5: Pago JGG | D5: JGG | E5: 0 | F5: 18000
A6: 45778 | B6: 2174 | C6: Pago RGL | D6: RGL | E6: 0 | F6: 18000
A7: 45748 | B7: 2174 | C7: Pago JGG | D7: JGG | E7: 0 | F7: 17500
A8: 45627 | B8: 2174 | C8: Pago JGG | D8: JGG | E8: 0 | F8: 17000
A9: 45566 | B9: 2174 | C9: Pago JGG | D9: JGG | E9: 0 | F9: 15600
A10: 45505 | B10: 2174 | C10: Pago JGG | D10: JGG | E10: 0 | F10: 15200
A11: 45793 | B11: 2174 | C11: Pago RGL-PENDIENTE | D11: RGL | E11: 0 | F11: 15000
A12: 45658 | B12: 2174 | C12: Pago RGL | D12: RGL | E12: 0 | F12: 14000
A13: 45748 | B13: 2171 | C13: Comisiones MAT | D13: MAT | E13: 0 | F13: 13831.407
... A42: 45611 | B42: 2174 | C42: Pago RGL | D42: RGL | E42: 0 | F42: 9348
A43: 45566 | B43: 2174 | C43: Pago RGL | D43: RGL | E43: 0 | F43: 9165 | H43: 10867
A44: 45505 | B44: 2171 | C44: Comisiones MAT | D44: MAT | E44: 0 | F44: 9084.8908 | H44: 1592
A45: 45612 | B45: 2172 | C45: Compensación extra MAT | D45: MAT | E45: 0 | F45: 8908
A46: 45322 | B46: 2171 | C46: Comisiones RGL del 15 al 30 de ene 24 | D46: RGL | E46: 0 | F46: 8810
A47: 45459 | B47: 2171 | C47: Comisiones MAT | D47: MAT | E47: 0 | F47: 8586.5677
A48: 45520 | B48: 2174 | C48: Pago RGL | D48: RGL | E48: 0 | F48: 8556
A49: 45536 | B49: 2174 | C49: Pago RGL | D49: RGL | E49: 0 | F49: 8450
A50: 45474 | B50: 2174 | C50: Pago RGL | D50: RGL | E50: 0 | F50: 8250
A51: 45382 | B51: 2171 | C51: Comisiones RGL del 15 al 30 de marzo 2424 | D51: RGL | E51: 0 | F51: 8249.13
A52: 45413 | B52: 2171 | C52: Pago RGL por horas | D52: RGL | E52: 0 | F52: 8100
A53: 45551 | B53: 2174 | C53: Pago RGL | D53: RGL | E53: 0 | F53: 8100
A54: 45397 | B54: 2171 | C54: Comisiones RGL del 15 al 30 de marzo 2424 | D54: RGL | E54: 0 | F54: 8079.8
A55: 45566 | B55: 2171 | C55: Comisiones MAT | D55: MAT | E55: 0 | F55: 8062.575
A56: 45641 | B56: 2174 | C56: Aguinaldo | D56: RGL | E56: 0 | F56: 8000
... A310: 45413 | B310: 2171 | C310: Comisiones ACP | D310: ACP | E310: 0 | F310: 2588.6964
A311: 45824 | B311: 2171 | C311: Comisiones AAT | D311: AAT | E311: 0 | F311: 2578.126 | I311: 4285
A312: 45322 | B312: 2172 | C312: Compensación por vacaciones MAT | D312: MAT | E312: 0 | F312: 2560.9925
A313: 45732 | B313: 2171 | C313: Comisiones JLP | D313: JLP | E313: 0 | F313: 2560.8
A314: 45717 | B314: 2171 | C314: Comisiones ACP | D314: ACP | E314: 0 | F314: 2559.3
A315: 45382 | B315: 2174 | C315: Apoyo para FCB | D315: FCB | E315: 0 | F315: 2556.79
A316: 45474 | B316: 2174 | C316: Pago FCB (Harbor) | D316: FCB | E316: 0 | F316: 2550
A317: 45551 | B317: 2174 | C317: Pago SNA | D317: SNA | E317: 0 | F317: 2550
A318: 45474 | B318: 2111 | C318: Sueldo ACP | D318: ACP | E318: 0 | F318: 2547.6
A319: 45489 | B319: 2111 | C319: Sueldo ACP | D319: ACP | E319: 0 | F319: 2547.6
A320: 45505 | B320: 2111 | C320: Sueldo ACP | D320: ACP | E320: 0 | F320: 2547.6
A321: 45520 | B321: 2111 | C321: Sueldo ACP | D321: ACP | E321: 0 | F321: 2547.6
...

Sheet payrollsOrig
A1: Date | B1: Código | C1: Concepto | D1: Beneficiario | E1: Ingreso | F1: Egreso
A2: 45306 | B2: 2111 | C2: Sueldo AAA | D2: AAA | E2: 0 | F2: 3920
A3: 45306 | B3: 2141 | C3: Retención IMSS AAA | D3: AAA | E3: 97.30863 | F3: 0
A4: 45306 | B4: 2812 | C4: Retención ISR AAA | D4: AAA | E4: 305.23085 | F4: 0
A5: 45322 | B5: 2111 | C5: Sueldo AAA | D5: AAA | E5: 0 | F5: 3920
A6: 45322 | B6: 2141 | C6: Retención IMSS AAA | D6: AAA | E6: 103.79587 | F6: 0
A7: 45322 | B7: 2812 | C7: Retención ISR AAA | D7: AAA | E7: 305.23085 | F7: 0
A8: 45337 | B8: 2111 | C8: Sueldo AAA | D8: AAA | E8: 0 | F8: 3920
A9: 45337 | B9: 2141 | C9: Retención IMSS AAA | D9: AAA | E9: 97.30863 | F9: 0
A10: 45337 | B10: 2812 | C10: Retención ISR AAA | D10: AAA | E10: 305.23085 | F10: 0
A11: 45351 | B11: 2111 | C11: Sueldo AAA | D11: AAA | E11: 0 | F11: 3920
A12: 45351 | B12: 2141 | C12: Retención IMSS AAA | D12: AAA | E12: 90.821388 | F12: 0
A13: 45351 | B13: 2812 | C13: Retención ISR AAA | D13: AAA | E13: 305.23085 | F13: 0
... A42: 45322 | B42: 2133 | C42: Horas extras AAT | D42: AAT | E42: 0 | F42: 59.873056
A43: 45322 | B43: 2134 | C43: Prima dominical AAT | D43: AAT | E43: 0 | F43: 39.28066 | H43: 10867
A44: 45322 | B44: 2141 | C44: Retención IMSS AAT | D44: AAT | E44: 49.250082 | F44: 0 | H44: 1592
A45: 45322 | B45: 2171 | C45: Comisiones AAT | D45: AAT | E45: 0 | F45: 882
A46: 45322 | B46: 2172 | C46: Compensación por alimentos AAT | D46: AAT | E46: 0 | F46: 550
A47: 45322 | B47: 2173 | C47: Bono de puntualidad AAT | D47: AAT | E47: 0 | F47: 124
A48: 45322 | B48: 2812 | C48: Retención ISR AAT | D48: AAT | E48: 193.81275 | F48: 0
A49: 45322 | B49: 2813 | C49: Subsidio para el empleo AAT | D49: AAT | E49: 0 | F49: 145.29754
A50: 45337 | B50: 2111 | C50: Sueldo AAT | D50: AAT | E50: 0 | F50: 1860
A51: 45337 | B51: 2133 | C51: Horas extras AAT | D51: AAT | E51: 0 | F51: 81.426667
A52: 45337 | B52: 2134 | C52: Prima dominical AAT | D52: AAT | E52: 0 | F52: 46.569965
A53: 45337 | B53: 2136 | C53: Día inhábil o de descanso AAT | D53: AAT | E53: 0 | F53: 402.20778
A54: 45337 | B54: 2141 | C54: Retención IMSS AAT | D54: AAT | E54: 46.171952 | F54: 0
A55: 45337 | B55: 2171 | C55: Comisiones AAT | D55: AAT | E55: 0 | F55: 781.2
A56: 45337 | B56: 2172 | C56: Compensación por alimentos AAT | D56: AAT | E56: 0 | F56: 450
... A2575: 45366 | B2575: 2812 | C2575: Retención ISR VGG | D2575: VGG | E2575: 18.597911 | F2575: 0

Sheet payrolls_duplicate
A1: Date | B1: Código | C1: Concepto | D1: Beneficiario | E1: Ingreso | F1: Egreso
A2: 45306 | B2: 2111 | C2: Sueldo AAA | D2: AAA | E2: 0 | F2: 3920
A3: 45306 | B3: 2111 | C3: Sueldo AAT | D3: AAT | E3: 0 | F3: 1860
A4: 45306 | B4: 2111 | C4: Sueldo ACP | D4: ACP | E4: 0 | F4: 2203.2
A5: 45306 | B5: 2111 | C5: Sueldo ADG | D5: ADG | E5: 0 | F5: 5445
A6: 45306 | B6: 2111 | C6: Sueldo FVC | D6: FVC | E6: 0 | F6: 1860
A7: 45306 | B7: 2111 | C7: Sueldo JLP | D7: JLP | E7: 0 | F7: 2460.64
A8: 45306 | B8: 2111 | C8: Sueldo MAT | D8: MAT | E8: 0 | F8: 3030
A9: 45306 | B9: 2111 | C9: Sueldo PCS | D9: PCS | E9: 0 | F9: 2203.2
A10: 45306 | B10: 2111 | C10: Sueldo SCP | D10: SCP | E10: 0 | F10: 2642.8929
A11: 45306 | B11: 2111 | C11: Sueldo VGG | D11: VGG | E11: 0 | F11: 1860
A12: 45322 | B12: 2111 | C12: Sueldo AAA | D12: AAA | E12: 0 | F12: 3920
A13: 45322 | B13: 2111 | C13: Sueldo AAT | D13: AAT | E13: 0 | F13: 1860
... A42: 45366 | B42: 2111 | C42: Sueldo AAA | D42: AAA | E42: 0 | F42: 3920
A43: 45366 | B43: 2111 | C43: Sueldo AAT | D43: AAT | E43: 0 | F43: 1934.4 | H43: 10867
A44: 45366 | B44: 2111 | C44: Sueldo ACP | D44: ACP | E44: 0 | F44: 2203.2 | H44: 1592
A45: 45366 | B45: 2111 | C45: Sueldo ADG | D45: ADG | E45: 0 | F45: 5445
A46: 45366 | B46: 2111 | C46: Sueldo FVC | D46: FVC | E46: 0 | F46: 1860
A47: 45366 | B47: 2111 | C47: Sueldo JLP | D47: JLP | E47: 0 | F47: 2361.84
A48: 45366 | B48: 2111 | C48: Sueldo MAT | D48: MAT | E48: 0 | F48: 2626
A49: 45366 | B49: 2111 | C49: Sueldo PCS | D49: PCS | E49: 0 | F49: 2203.2
A50: 45366 | B50: 2111 | C50: Sueldo SCP | D50: SCP | E50: 0 | F50: 3143.8333
A51: 45366 | B51: 2111 | C51: Sueldo VGG | D51: VGG | E51: 0 | F51: 401.17647
A52: 45382 | B52: 2111 | C52: Sueldo AAA | D52: AAA | E52: 0 | F52: 3920
A53: 45382 | B53: 2111 | C53: Sueldo AAT | D53: AAT | E53: 0 | F53: 1934.4
A54: 45382 | B54: 2111 | C54: Sueldo ACP | D54: ACP | E54: 0 | F54: 2203.2
A55: 45382 | B55: 2111 | C55: Sueldo ADG | D55: ADG | E55: 0 | F55: 5445
A56: 45382 | B56: 2111 | C56: Sueldo FVC | D56: FVC | E56: 0 | F56: 1860
... A2772: 45824 | B2772: 2813 | C2772: Subsidio para el empleo SLR | D2772: SLR | E2772: 0 | F2772: 192.38868

Sheet colData
A1: Date | B1: Código | C1: Código | D1: Nombre | E1: Puesto | F1: Jornada | G1: Salario | H1: DIF | I1: IM | J1: SBC | K1: SPD | L1: Forma de pago | M1: IMSS | N1: CURP | O1: IMSS | P1: RFC | Q1: starting | R1: end | S1: seniority | T1: adjusted | U1: hourly | V1: GUARANTEED
A2: 45306 | B2: 24 | C2: AAA | D2: Jesús Adrián Aguilar Ávila | E2: Gerente | F2: 48 | G2: 7840 | H2: =IFERROR(G2-G1,0) -> 0 | I2: 7000 | J2: 273.14703 | K2: 317.88166 | L2: Garantizado | Q2: =VLOOKUP(C2,employees!$A$1:$C$31,2,FALSE()) -> 43647 | R2: =VLOOKUP(C2,employees!$A$1:$C$31,3,FALSE()) -> 45427 | S2: =ORG.OPENOFFICE.YEARS(Q2,A2,0)*0.04 -> 0.16 | T2: =G2/(1+S2) -> 6758.6207 | U2: =T2/4.34/48 -> 32.443456 | V2: =T2/0.6 -> 11264.368
A3: 45306 | B3: 43 | C3: AAT | D3: Alejandra Isabel Ayora Troncoso | E3: Asistente B | F3: 48 | G3: 3720 | H3: =IFERROR(G3-G2,0) -> -4120 | I3: 5100 | J3: 129.60548 | K3: 180.9687 | L3: Formal | Q3: =VLOOKUP(C3,employees!$A$1:$C$31,2,FALSE()) -> 44942 | R3: =VLOOKUP(C3,employees!$A$1:$C$31,3,FALSE()) -> Present | S3: =ORG.OPENOFFICE.YEARS(Q3,A3,0)*0.04 -> 0 | T3: =G3/(1+S3) -> 3720 | U3: =T3/4.34/48 -> 17.857143 | V3: =T3/0.6 -> 6200
A4: 45306 | B4: 41 | C4: ACP | D4: Amayrani Chan Pique | E4: Asistente A | F4: 48 | G4: 4406.4 | H4: =IFERROR(G4-G3,0) -> 686.4 | I4: 5700 | J4: 153.51978 | K4: 236.13734 | L4: Formal | Q4: =VLOOKUP(C4,employees!$A$1:$C$31,2,FALSE()) -> 44495 | R4: =VLOOKUP(C4,employees!$A$1:$C$31,3,FALSE()) -> 45767 | S4: =ORG.OPENOFFICE.YEARS(Q4,A4,0)*0.04 -> 0.08 | T4: =G4/(1+S4) -> 4080 | U4: =T4/4.34/48 -> 19.585253 | V4: =T4/0.6 -> 6800
A5: 45306 | B5: 4 | C5: ADG | D5: Aida Adriana García Aguilar | E5: Directora administrativa | F5: 48 | G5: 10890 | H5: =IFERROR(G5-G4,0) -> 6483.6 | I5: 9000 | J5: 379.40959 | K5: 320.05479 | L5: Garantizado | Q5: =VLOOKUP(C5,employees!$A$1:$C$31,2,FALSE()) -> 42720 | R5: =VLOOKUP(C5,employees!$A$1:$C$31,3,FALSE()) -> 45427 | S5: =ORG.OPENOFFICE.YEARS(Q5,A5,0)*0.04 -> 0.28 | T5: =G5/(1+S5) -> 8507.8125 | U5: =T5/4.34/48 -> 40.840114 | V5: =T5/0.6 -> 14179.688
A6: 45306 | B6: 47 | C6: FCB | D6: Felisa Andrea Ceballos Balam | E6: Pasante | F6: 27 | G6: 1406.25 | H6: =IFERROR(G6-G5,0) -> -9483.75 | I6: 1406.25 | J6: 48.994007 | K6: 68.610169 | L6: Informal | Q6: =VLOOKUP(C6,employees!$A$1:$C$31,2,FALSE()) -> 45173 | R6: =VLOOKUP(C6,employees!$A$1:$C$31,3,FALSE()) -> 45550 | S6: =ORG.OPENOFFICE.YEARS(Q6,A6,0)*0.04 -> 0 | T6: =G6/(1+S6) -> 1406.25 | U6: =T6/4.34/48 -> 6.750432 | V6: =T6/0.6 -> 2343.75
A7: 45306 | B7: 44 | C7: FVC | D7: Felix Jared Velazquez Couoh | E7: Asistente B | F7: 48 | G7: 3720 | H7: =IFERROR(G7-G6,0) -> 2313.75 | I7: 5100 | J7: 129.60548 | K7: 181.57021 | L7: Formal | Q7: =VLOOKUP(C7,employees!$A$1:$C$31,2,FALSE()) -> 44999 | R7: =VLOOKUP(C7,employees!$A$1:$C$31,3,FALSE()) -> 45788 | S7: =ORG.OPENOFFICE.YEARS(Q7,A7,0)*0.04 -> 0 | T7: =G7/(1+S7) -> 3720 | U7: =T7/4.34/48 -> 17.857143 | V7: =T7/0.6 -> 6200
A8: 45306 | B8: 33 | C8: JLP | D8: José Luis López Pérez | E8: Veterinario B | F8: 48 | G8: 5272.8 | H8: =IFERROR(G8-G7,0) -> 1552.8 | I8: 7200 | J8: 183.70532 | K8: 338.86076 | L8: Formal | Q8: =VLOOKUP(C8,employees!$A$1:$C$31,2,FALSE()) -> 43854 | R8: =VLOOKUP(C8,employees!$A$1:$C$31,3,FALSE()) -> Present | S8: =ORG.OPENOFFICE.YEARS(Q8,A8,0)*0.04 -> 0.12 | T8: =G8/(1+S8) -> 4707.8571 | U8: =T8/4.34/48 -> 22.599161 | V8: =T8/0.6 -> 7846.4286
A9: 45306 | B9: 42 | C9: LCM | D9: Lizeth Haydee Canul Manzanilla | E9: Pasante | F9: 36 | G9: 1950 | H9: =IFERROR(G9-G8,0) -> -3322.8 | I9: 1875 | J9: 67.938356 | K9: 108.9611 | L9: Informal | Q9: =VLOOKUP(C9,employees!$A$1:$C$31,2,FALSE()) -> 44908 | R9: =VLOOKUP(C9,employees!$A$1:$C$31,3,FALSE()) -> Present | S9: =ORG.OPENOFFICE.YEARS(Q9,A9,0)*0.04 -> 0.04 | T9: =G9/(1+S9) -> 1875 | U9: =T9/4.34/48 -> 9.000576 | V9: =T9/0.6 -> 3125
A10: 45306 | B10: 18 | C10: MAT | D10: María de Lourdes Avendaño Talarico | E10: Veterinario A | F10: 48 | G10: 6060 | H10: =IFERROR(G10-G9,0) -> 4110 | I10: 9600 | J10: 211.13151 | K10: 628.83209 | L10: Formal | Q10: =VLOOKUP(C10,employees!$A$1:$C$31,2,FALSE()) -> 43327 | R10: =VLOOKUP(C10,employees!$A$1:$C$31,3,FALSE()) -> Present | S10: =ORG.OPENOFFICE.YEARS(Q10,A10,0)*0.04 -> 0.2 | T10: =G10/(1+S10) -> 5050 | U10: =T10/4.34/48 -> 24.241551 | V10: =T10/0.6 -> 8416.6667
A11: 45306 | B11: 39 | C11: PCS | D11: Paola Aracely Carvajal Sanchez | E11: Asistente A | F11: 48 | G11: 4406.4 | H11: =IFERROR(G11-G10,0) -> -1653.6 | I11: 5700 | J11: 153.51978 | K11: 241.6964 | L11: Formal | Q11: =VLOOKUP(C11,employees!$A$1:$C$31,2,FALSE()) -> 44396 | R11: =VLOOKUP(C11,employees!$A$1:$C$31,3,FALSE()) -> 45766 | S11: =ORG.OPENOFFICE.YEARS(Q11,A11,0)*0.04 -> 0.08 | T11: =G11/(1+S11) -> 4080 | U11: =T11/4.34/48 -> 19.585253 | V11: =T11/0.6 -> 6800
A12: 45306 | B12: 2 | C12: RGL | D12: Rafael Augusto García López | E12: Director médico | F12: 48 | G12: 32550 | H12: =IFERROR(G12-G11,0) -> 28143.6 | I12: 0 | J12: 0 | K12: 142.94795 | L12: NA | Q12: =VLOOKUP(C12,employees!$A$1:$C$31,2,FALSE()) -> 42705 | R12: =VLOOKUP(C12,employees!$A$1:$C$31,3,FALSE()) -> Present | S12: =ORG.OPENOFFICE.YEARS(Q12,A12,0)*0.04 -> 0.28 | T12: =G12/(1+S12) -> 25429.688 | U12: =T12/4.34/48 -> 122.07031 | V12: =T12/0.6 -> 42382.812
A13: 45306 | B13: 12 | C13: SCP | D13: Silvia Guadalupe Colmenares Piña | E13: Recepcionista | F13: 42 | G13: 7255 | H13: =IFERROR(G13-G12,0) -> -25295 | I13: 5250 | J13: 252.76553 | K13: 211.27988 | L13: Formal | Q13: =VLOOKUP(C13,employees!$A$1:$C$31,2,FALSE()) -> 43011 | R13: =VLOOKUP(C13,employees!$A$1:$C$31,3,FALSE()) -> Present | S13: =ORG.OPENOFFICE.YEARS(Q13,A13,0)*0.04 -> 0.24 | T13: =G13/(1+S13) -> 5850.8065 | U13: =T13/4.34/48 -> 28.085668 | V13: =T13/0.6 -> 9751.3441
... A15: 45306 | B15: 45 | C15: VGG | D15: Victoria del Carmen Garcia Gonzalez | E15: Asistente B | F15: 48 | G15: 3720 | H15: =IFERROR(G15-G14,0) -> 2574.1667 | I15: 5100 | J15: 129.60548 | K15: 159.92451 | L15: Formal | Q15: =VLOOKUP(C15,employees!$A$1:$C$31,2,FALSE()) -> 45063 | R15: =VLOOKUP(C15,employees!$A$1:$C$31,3,FALSE()) -> 45355 | S15: =ORG.OPENOFFICE.YEARS(Q15,A15,0)*0.04 -> 0 | T15: =G15/(1+S15) -> 3720 | U15: =T15/4.34/48 -> 17.857143 | V15: =T15/0.6 -> 6200
A16: 45322 | B16: 24 | C16: AAA | D16: Jesús Adrián Aguilar Ávila | E16: Gerente | F16: 48 | G16: 7840 | H16: =IFERROR(G16-G15,0) -> 4120 | I16: 7000 | J16: 273.14703 | K16: 317.88166 | L16: Garantizado | Q16: =VLOOKUP(C16,employees!$A$1:$C$31,2,FALSE()) -> 43647 | R16: =VLOOKUP(C16,employees!$A$1:$C$31,3,FALSE()) -> 45427 | S16: =ORG.OPENOFFICE.YEARS(Q16,A16,0)*0.025 -> 0.1 | T16: =G16/(1+S16) -> 7127.2727
A17: 45322 | B17: 43 | C17: AAT | D17: Alejandra Isabel Ayora Troncoso | E17: Asistente B | F17: 48 | G17: 3720 | H17: =IFERROR(G17-G16,0) -> -4120 | I17: 5100 | J17: 129.60548 | K17: 180.9687 | L17: Formal | Q17: =VLOOKUP(C17,employees!$A$1:$C$31,2,FALSE()) -> 44942 | R17: =VLOOKUP(C17,employees!$A$1:$C$31,3,FALSE()) -> Present | S17: =ORG.OPENOFFICE.YEARS(Q17,A17,0)*0.025 -> 0.025 | T17: =G17/(1+S17) -> 3629.2683
A18: 45322 | B18: 41 | C18: ACP | D18: Amayrani Chan Pique | E18: Asistente A | F18: 48 | G18: 4406.4 | H18: =IFERROR(G18-G17,0) -> 686.4 | I18: 5700 | J18: 153.51978 | K18: 236.13734 | L18: Formal | Q18: =VLOOKUP(C18,employees!$A$1:$C$31,2,FALSE()) -> 44495 | R18: =VLOOKUP(C18,employees!$A$1:$C$31,3,FALSE()) -> 45767 | S18: =ORG.OPENOFFICE.YEARS(Q18,A18,0)*0.025 -> 0.05 | T18: =G18/(1+S18) -> 4196.5714
A19: 45322 | B19: 4 | C19: ADG | D19: Aida Adriana García Aguilar | E19: Directora administrativa | F19: 48 | G19: 10890 | H19: =IFERROR(G19-G18,0) -> 6483.6 | I19: 9000 | J19: 379.40959 | K19: 320.05479 | L19: Garantizado | Q19: =VLOOKUP(C19,employees!$A$1:$C$31,2,FALSE()) -> 42720 | R19: =VLOOKUP(C19,employees!$A$1:$C$31,3,FALSE()) -> 45427 | S19: =ORG.OPENOFFICE.YEARS(Q19,A19,0)*0.025 -> 0.175 | T19: =G19/(1+S19) -> 9268.0851
A20: 45322 | B20: 47 | C20: FCB | D20: Felisa Andrea Ceballos Balam | E20: Pasante | F20: 27 | G20: 1406.25 | H20: =IFERROR(G20-G19,0) -> -9483.75 | I20: 1406.25 | J20: 48.994007 | K20: 68.610169 | L20: Informal | Q20: =VLOOKUP(C20,employees!$A$1:$C$31,2,FALSE()) -> 45173 | R20: =VLOOKUP(C20,employees!$A$1:$C$31,3,FALSE()) -> 45550 | S20: =ORG.OPENOFFICE.YEARS(Q20,A20,0)*0.025 -> 0 | T20: =G20/(1+S20) -> 1406.25
A21: 45322 | B21: 44 | C21: FVC | D21: Felix Jared Velazquez Couoh | E21: Asistente B | F21: 48 | G21: 3720 | H21: =IFERROR(G21-G20,0) -> 2313.75 | I21: 5100 | J21: 129.60548 | K21: 181.57021 | L21: Formal | Q21: =VLOOKUP(C21,employees!$A$1:$C$31,2,FALSE()) -> 44999 | R21: =VLOOKUP(C21,employees!$A$1:$C$31,3,FALSE()) -> 45788 | S21: =ORG.OPENOFFICE.YEARS(Q21,A21,0)*0.025 -> 0 | T21: =G21/(1+S21) -> 3720
A22: 45322 | B22: 33 | C22: JLP | D22: José Luis López Pérez | E22: Veterinario B | F22: 48 | G22: 5272.8 | H22: =IFERROR(G22-G21,0) -> 1552.8 | I22: 7200 | J22: 183.70532 | K22: 338.86076 | L22: Formal | Q22: =VLOOKUP(C22,employees!$A$1:$C$31,2,FALSE()) -> 43854 | R22: =VLOOKUP(C22,employees!$A$1:$C$31,3,FALSE()) -> Present | S22: =ORG.OPENOFFICE.YEARS(Q22,A22,0)*0.025 -> 0.1 | T22: =G22/(1+S22) -> 4793.4545
A23: 45322 | B23: 42 | C23: LCM | D23: Lizeth Haydee Canul Manzanilla | E23: Pasante | F23: 36 | G23: 1950 | H23: =IFERROR(G23-G22,0) -> -3322.8 | I23: 1875 | J23: 67.938356 | K23: 108.9611 | L23: Informal | Q23: =VLOOKUP(C23,employees!$A$1:$C$31,2,FALSE()) -> 44908 | R23: =VLOOKUP(C23,employees!$A$1:$C$31,3,FALSE()) -> Present | S23: =ORG.OPENOFFICE.YEARS(Q23,A23,0)*0.025 -> 0.025 | T23: =G23/(1+S23) -> 1902.439
A24: 45322 | B24: 18 | C24: MAT | D24: María de Lourdes Avendaño Talarico | E24: Veterinario A | F24: 48 | G24: 6060 | H24: =IFERROR(G24-G23,0) -> 4110 | I24: 9600 | J24: 211.13151 | K24: 628.83209 | L24: Formal | Q24: =VLOOKUP(C24,employees!$A$1:$C$31,2,FALSE()) -> 43327 | R24: =VLOOKUP(C24,employees!$A$1:$C$31,3,FALSE()) -> Present | S24: =ORG.OPENOFFICE.YEARS(Q24,A24,0)*0.025 -> 0.125 | T24: =G24/(1+S24) -> 5386.6667
A25: 45322 | B25: 39 | C25: PCS | D25: Paola Aracely Carvajal Sanchez | E25: Asistente A | F25: 48 | G25: 4406.4 | H25: =IFERROR(G25-G24,0) -> -1653.6 | I25: 5700 | J25: 153.51978 | K25: 241.6964 | L25: Formal | Q25: =VLOOKUP(C25,employees!$A$1:$C$31,2,FALSE()) -> 44396 | R25: =VLOOKUP(C25,employees!$A$1:$C$31,3,FALSE()) -> 45766 | S25: =ORG.OPENOFFICE.YEARS(Q25,A25,0)*0.025 -> 0.05 | T25: =G25/(1+S25) -> 4196.5714
A26: 45322 | B26: 2 | C26: RGL | D26: Rafael Augusto García López | E26: Director médico | F26: 48 | G26: 0 | H26: =IFERROR(G26-G25,0) -> -4406.4 | I26: 0 | J26: 0 | K26: 142.94795 | L26: NA | Q26: =VLOOKUP(C26,employees!$A$1:$C$31,2,FALSE()) -> 42705 | R26: =VLOOKUP(C26,employees!$A$1:$C$31,3,FALSE()) -> Present | S26: =ORG.OPENOFFICE.YEARS(Q26,A26,0)*0.025 -> 0.175 | T26: =G26/(1+S26) -> 0
A27: 45322 | B27: 12 | C27: SCP | D27: Silvia Guadalupe Colmenares Piña | E27: Recepcionista | F27: 42 | G27: 7255 | H27: =IFERROR(G27-G26,0) -> 7255 | I27: 5250 | J27: 252.76553 | K27: 211.27988 | L27: Formal | Q27: =VLOOKUP(C27,employees!$A$1:$C$31,2,FALSE()) -> 43011 | R27: =VLOOKUP(C27,employees!$A$1:$C$31,3,FALSE()) -> Present | S27: =ORG.OPENOFFICE.YEARS(Q27,A27,0)*0.025 -> 0.15 | T27: =G27/(1+S27) -> 6308.6957
... A83: 45382 | B83: 12 | C83: SCP | D83: Silvia Guadalupe Colmenares Piña | E83: Recepcionista | F83: 42 | G83: 7255 | H83: =IFERROR(G83-G82,0) -> 7255 | I83: 5250 | J83: 252.76553 | K83: 230.92894 | L83: Formal | Q83: =VLOOKUP(C83,employees!$A$1:$C$31,2,FALSE()) -> 43011 | R83: =VLOOKUP(C83,employees!$A$1:$C$31,3,FALSE()) -> Present | S83: =ORG.OPENOFFICE.YEARS(Q83,A83,0)*0.025 -> 0.15 | T83: =G83/(1+S83) -> 6308.6957
A84: 45397 | B84: 24 | C84: AAA | D84: Jesús Adrián Aguilar Ávila | E84: Gerente | F84: 48 | G84: 7840 | H84: =IFERROR(G84-G83,0) -> 585 | I84: 7000 | J84: 273.14703 | K84: 325.82521 | L84: Garantizado | M84: 1 | N84: AUAJ871013HYNGVS02 | O84: 3168785453 | P84: AUAJ871013LM6 | Q84: =VLOOKUP(C84,employees!$A$1:$C$31,2,FALSE()) -> 43647 | R84: =VLOOKUP(C84,employees!$A$1:$C$31,3,FALSE()) -> 45427 | S84: =ORG.OPENOFFICE.YEARS(Q84,A84,0)*0.025 -> 0.1 | T84: =G84/(1+S84) -> 7127.2727
A85: 45397 | B85: 43 | C85: AAT | D85: Alejandra Isabel Ayora Troncoso | E85: Asistente A | F85: 48 | G85: 4243.2 | H85: =IFERROR(G85-G84,0) -> -3596.8 | I85: 5700 | J85: 218.04524 | K85: 198.63395 | L85: Formal | M85: 1 | N85: AOTA990618MYNYRL05 | O85: 14139978077 | P85: AOTA990618RA9 | Q85: =VLOOKUP(C85,employees!$A$1:$C$31,2,FALSE()) -> 44942 | R85: =VLOOKUP(C85,employees!$A$1:$C$31,3,FALSE()) -> Present | S85: =ORG.OPENOFFICE.YEARS(Q85,A85,0)*0.025 -> 0.025 | T85: =G85/(1+S85) -> 4139.7073
A86: 45397 | B86: 41 | C86: ACP | D86: Amayrani Chan Pique | E86: Veterinario B | F86: 48 | G86: 4795.2 | H86: =IFERROR(G86-G85,0) -> 552 | I86: 7200 | J86: 265.65195 | K86: 255.30755 | L86: Formal | M86: 1 | N86: CAPA970614MYNHQM01 | O86: 1139778375 | P86: CAPA970614622 | Q86: =VLOOKUP(C86,employees!$A$1:$C$31,2,FALSE()) -> 44495 | R86: =VLOOKUP(C86,employees!$A$1:$C$31,3,FALSE()) -> 45767 | S86: =ORG.OPENOFFICE.YEARS(Q86,A86,0)*0.025 -> 0.05 | T86: =G86/(1+S86) -> 4566.8571
A87: 45397 | B87: 4 | C87: ADG | D87: Aida Adriana García Aguilar | E87: Directora administrativa | F87: 48 | G87: 10890 | H87: =IFERROR(G87-G86,0) -> 6094.8 | I87: 9000 | J87: 379.40959 | K87: 334.79508 | L87: Garantizado | M87: 1 | N87: GAAA900526MPLRGD00 | O87: 3149097176 | P87: GAAA900526IQ1 | Q87: =VLOOKUP(C87,employees!$A$1:$C$31,2,FALSE()) -> 42720 | R87: =VLOOKUP(C87,employees!$A$1:$C$31,3,FALSE()) -> 45427 | S87: =ORG.OPENOFFICE.YEARS(Q87,A87,0)*0.025 -> 0.175 | T87: =G87/(1+S87) -> 9268.0851
A88: 45397 | B88: 47 | C88: FCB | D88: Felisa Andrea Ceballos Balam | E88: Pasante | F88: 35 | G88: 3011.249 | H88: =IFERROR(G88-G87,0) -> -7878.751 | I88: 2281.249 | J88: 76.594007 | K88: 81.787219 | L88: Por horas | M88: 0 | N88: CEBF010615MYNBLLA0 | Q88: =VLOOKUP(C88,employees!$A$1:$C$31,2,FALSE()) -> 45173 | R88: =VLOOKUP(C88,employees!$A$1:$C$31,3,FALSE()) -> 45550 | S88: =ORG.OPENOFFICE.YEARS(Q88,A88,0)*0.025 -> 0 | T88: =G88/(1+S88) -> 3011.249
A89: 45397 | B89: 44 | C89: FVC | D89: Felix Jared Velazquez Couoh | E89: Asistente A | F89: 48 | G89: 4243.2 | H89: =IFERROR(G89-G88,0) -> 1231.951 | I89: 5700 | J89: 183.29465 | K89: 194.51967 | L89: Formal | M89: 1 | N89: VECF981022HYNLHL04 | P89: VECF9810224E2 | Q89: =VLOOKUP(C89,employees!$A$1:$C$31,2,FALSE()) -> 44999 | R89: =VLOOKUP(C89,employees!$A$1:$C$31,3,FALSE()) -> 45788 | S89: =ORG.OPENOFFICE.YEARS(Q89,A89,0)*0.025 -> 0.025 | T89: =G89/(1+S89) -> 4139.7073
A90: 45397 | B90: 33 | C90: JLP | D90: José Luis López Pérez | E90: Veterinario B | F90: 48 | G90: 5450.4 | H90: =IFERROR(G90-G89,0) -> 1207.2 | I90: 7200 | J90: 337.38258 | K90: 346.38204 | L90: Formal | M90: 1 | N90: LOPL931009HCSPRS05 | O90: 62169374543 | P90: LOPL9310092R8 | Q90: =VLOOKUP(C90,employees!$A$1:$C$31,2,FALSE()) -> 43854 | R90: =VLOOKUP(C90,employees!$A$1:$C$31,3,FALSE()) -> Present | S90: =ORG.OPENOFFICE.YEARS(Q90,A90,0)*0.025 -> 0.1 | T90: =G90/(1+S90) -> 4954.9091
A91: 45397 | B91: 42 | C91: LCM | D91: Lizeth Haydee Canul Manzanilla | E91: Pasante | F91: 37 | G91: 3278.0703 | H91: =IFERROR(G91-G90,0) -> -2172.3297 | I91: 2411.606 | J91: 120.84981 | K91: 118.1583 | L91: Por horas | M91: 0 | N91: CAML980925MYNNNZ09 | Q91: =VLOOKUP(C91,employees!$A$1:$C$31,2,FALSE()) -> 44908 | R91: =VLOOKUP(C91,employees!$A$1:$C$31,3,FALSE()) -> Present | S91: =ORG.OPENOFFICE.YEARS(Q91,A91,0)*0.025 -> 0.025 | T91: =G91/(1+S91) -> 3198.1173
A92: 45397 | B92: 18 | C92: MAT | D92: María de Lourdes Avendaño Talarico | E92: Veterinario A | F92: 48 | G92: 6060 | H92: =IFERROR(G92-G91,0) -> 2781.9297 | I92: 9600 | J92: 679.95399 | K92: 685.77479 | L92: Formal | M92: 1 | N92: AETL911129MCSVLR02 | O92: 62169127248 | P92: AETL911129HI5 | Q92: =VLOOKUP(C92,employees!$A$1:$C$31,2,FALSE()) -> 43327 | R92: =VLOOKUP(C92,employees!$A$1:$C$31,3,FALSE()) -> Present | S92: =ORG.OPENOFFICE.YEARS(Q92,A92,0)*0.025 -> 0.125 | T92: =G92/(1+S92) -> 5386.6667
A93: 45397 | B93: 39 | C93: PCS | D93: Paola Aracely Carvajal Sanchez | E93: Veterinario B | F93: 48 | G93: 4795.2 | H93: =IFERROR(G93-G92,0) -> -1264.8 | I93: 7200 | J93: 257.48464 | K93: 264.83856 | L93: Formal | M93: 1 | N93: CASP960514MYNRNL01 | O93: 1139669566 | Q93: =VLOOKUP(C93,employees!$A$1:$C$31,2,FALSE()) -> 44396 | R93: =VLOOKUP(C93,employees!$A$1:$C$31,3,FALSE()) -> 45766 | S93: =ORG.OPENOFFICE.YEARS(Q93,A93,0)*0.025 -> 0.05 | T93: =G93/(1+S93) -> 4566.8571
A94: 45397 | B94: 2 | C94: RGL | D94: Rafael Augusto García López | E94: Director médico | F94: 48 | G94: 0 | H94: =IFERROR(G94-G93,0) -> -4795.2 | I94: 0 | J94: 0 | K94: 0 | L94: NA | M94: 0 | N94: GALR671117HYNRPF07 | O94: 84936700065 | P94: GALR6711178Z9 | Q94: =VLOOKUP(C94,employees!$A$1:$C$31,2,FALSE()) -> 42705 | R94: =VLOOKUP(C94,employees!$A$1:$C$31,3,FALSE()) -> Present | S94: =ORG.OPENOFFICE.YEARS(Q94,A94,0)*0.025 -> 0.175 | T94: =G94/(1+S94) -> 0
A95: 45397 | B95: 12 | C95: SCP | D95: Silvia Guadalupe Colmenares Piña | E95: Recepcionista | F95: 42 | G95: 7255 | H95: =IFERROR(G95-G94,0) -> 7255 | I95: 5250 | J95: 252.76553 | K95: 230.92894 | L95: Formal | M95: 1 | N95: COPS701129MDFLXL05 | O95: 7887006380 | P95: COPS7011291S6 | Q95: =VLOOKUP(C95,employees!$A$1:$C$31,2,FALSE()) -> 43011 | R95: =VLOOKUP(C95,employees!$A$1:$C$31,3,FALSE()) -> Present | S95: =ORG.OPENOFFICE.YEARS(Q95,A95,0)*0.025 -> 0.15 | T95: =G95/(1+S95) -> 6308.6957
A96: 45397 | B96: 46 | C96: SNA | D96: Sandra Guadalupe Narvaez Arjona | E96: Pasante | F96: 22 | G96: 1433.9279 | H96: =IFERROR(G96-G95,0) -> -5821.0721 | I96: 1433.9279 | J96: 71.424283 | K96: 77.371321 | L96: Informal | M96: 0 | N96: NAAS001204MYNRRNA1 | P96: VECF9810224E2 | Q96: =VLOOKUP(C96,employees!$A$1:$C$31,2,FALSE()) -> 45166 | R96: =VLOOKUP(C96,employees!$A$1:$C$31,3,FALSE()) -> 45641 | S96: =ORG.OPENOFFICE.YEARS(Q96,A96,0)*0.025 -> 0 | T96: =G96/(1+S96) -> 1433.9279
...

Sheet payDates
A1: Pagos de nomina
A2: 45293
A3: 45306
A4: 45322
A5: 45337
A6: 45351
A7: 45366
A8: 45383
A9: 45397
A10: 45414
A11: 45428
A12: 45446
A13: 45460
... A36: 45810

Sheet employees
A1: COL_CODE | B1: START_DATE | C1: END_DATE
A2: VGG | B2: 45063 | C2: 45355
A3: ADG | B3: 42720 | C3: 45427
A4: AAA | B4: 43647 | C4: 45427
A5: ERP | B5: 45460 | C5: 45535
A6: FCB | B6: 45173 | C6: 45550
A7: SNA | B7: 45166 | C7: 45641
A8: GPP | B8: 43100 | C8: 45657
A9: TTT | B9: 44561 | C9: 45657
A10: KPS | B10: 45509 | C10: 45739
A11: KNB | B11: 45614 | C11: 45763
A12: PCS | B12: 44396 | C12: 45766
A13: ACP | B13: 44495 | C13: 45767
... A15: CRR | B15: 45778 | C15: 45801
A16: JGG | B16: 42705 | C16: Present
A17: RGL | B17: 42705 | C17: Present
A18: AGA | B18: 42705 | C18: Present
A19: SCP | B19: 43011 | C19: Present
A20: MAT | B20: 43327 | C20: Present
A21: JLP | B21: 43854 | C21: Present
A22: LCM | B22: 44908 | C22: Present
A23: AAT | B23: 44942 | C23: Present
A24: GUI | B24: 45413 | C24: Present
A25: FPO | B25: 45772 | C25: Present
A26: CGP | B26: 45778 | C26: Present
A27: SLR | B27: 45779 | C27: Present
... A31: LMP | B31: 45824 | C31: Present

Sheet Sheet5
A1: Data | B1: Código | C1: Concepto | D1: Beneficiario | E1: Ingreso | F1: Egreso
A2: 45322 | B2: 2111 | C2: Apoyo AGA | D2: AGA | E2: 0 | F2: 1400
A3: 45397 | B3: 2111 | C3: Vacaciones proporcionales NDC | D3: NDC | E3: 0 | F3: 5000
A4: 45419 | B4: 2111 | C4: Pago NDC | D4: NDC | E4: 0 | F4: 5000
A5: 45421 | B5: 2111 | C5: NESTOR | D5: NDC | E5: 0 | F5: 509
A6: 45356 | B6: 2137 | C6: Aguinaldo proporcional NDC | D6: NDC | E6: 0 | F6: 5000
A7: 45459 | B7: 2155 | C7: Pago MAT curso | D7: MAT | E7: 0 | F7: 5000
A8: 45413 | B8: 2171 | C8: Pago AIDA | D8: GUI | E8: 0 | F8: 600
A9: 45306 | B9: 2171 | C9: Pago RGL por horas | D9: RGL | E9: 0 | F9: 2850
A10: 45322 | B10: 2171 | C10: Comisiones RGL del 15 al 30 de ene 24 | D10: RGL | E10: 0 | F10: 8810
A11: 45337 | B11: 2171 | C11: Comisiones RGL del 15 al 30 de ene 24 | D11: RGL | E11: 0 | F11: 7590
A12: 45351 | B12: 2171 | C12: Comisiones RGL del 15 al 29 de feb 24 | D12: RGL | E12: 0 | F12: 5000
A13: 45366 | B13: 2171 | C13: Comisiones RGL del 30 de feb al 14 de marzo 24 | D13: RGL | E13: 0 | F13: 5725
... A198: 45672 | B198: 2174 | C198: Pago KNB | D198: SNA | E198: 0 | F198: 2600
